<?xml version="1.0" ?>
<!-- =================================================================================== -->
<!-- |    This document was autogenerated by xacro from servo.xacro                    | -->
<!-- |    EDITING THIS FILE BY HAND IS NOT RECOMMENDED                                 | -->
<!-- =================================================================================== -->
<robot name="servo" xmlns:xacro="http://www.ros.org/wiki/xacro">
  <material name="black">
    <color rgba="0.0 0.0 0.0 1.0"/>
  </material>
  <material name="blue">
    <color rgba="0.0 0.0 0.8 1.0"/>
  </material>
  <material name="green">
    <color rgba="0.0 0.8 0.0 1.0"/>
  </material>
  <material name="grey">
    <color rgba="0.2 0.2 0.2 1.0"/>
  </material>
  <material name="orange">
    <color rgba="1.0 0.423529411765 0.0392156862745 1.0"/>
  </material>
  <material name="brown">
    <color rgba="0.870588235294 0.811764705882 0.764705882353 1.0"/>
  </material>
  <material name="red">
    <color rgba="0.8 0.0 0.0 1.0"/>
  </material>
  <material name="white">
    <color rgba="1.0 1.0 1.0 1.0"/>
  </material>
  <!--the fixed world link-->
  <link name="world"/>
  <!--the fixed link from world to servo iteself-->
  <joint name="world_to_u0" type="fixed">
    <origin rpy="0 0 0" xyz="0 0 0"/>
    <parent link="world"/>
    <child link="u0"/>
  </joint>
  <link name="u0">
    <visual>
      <origin rpy="0 0 0" xyz="0 0 0.005"/>
      <geometry>
        <box size="0.02 0.04 0.01"/>
      </geometry>
      <material name="black"/>
    </visual>
    <inertial>
      <origin rpy="0 0 0" xyz="0 0 0.005"/>
      <mass value="0.0136"/>
      <inertia ixx="1.92666666667e-06" ixy="0.0" ixz="0.0" iyy="5.66666666667e-07" iyz="0.0" izz="2.26666666667e-06"/>
    </inertial>
    <collision>
      <origin rpy="0 0 0" xyz="0 0 0.005"/>
      <geometry>
        <box size="0.02 0.04 0.01"/>
      </geometry>
    </collision>
  </link>
  <joint name="fix_1" type="fixed">
    <parent link="u0"/>
    <child link="u1"/>
    <origin xyz="0 0 0.01"/>
    <axis xyz="0 0 1"/>
  </joint>
  <link name="u1">
    <visual>
      <origin rpy="0 0 0" xyz="0 0 0.0085"/>
      <geometry>
        <box size="0.02 0.04 0.017"/>
      </geometry>
      <material name="orange"/>
    </visual>
    <inertial>
      <origin rpy="0 0 0" xyz="0 0 0.0085"/>
      <mass value="0.02312"/>
      <inertia ixx="3.63947333333e-06" ixy="0.0" ixz="0.0" iyy="1.32747333333e-06" iyz="0.0" izz="3.85333333333e-06"/>
    </inertial>
    <collision>
      <origin rpy="0 0 0" xyz="0 0 0.0085"/>
      <geometry>
        <box size="0.02 0.04 0.017"/>
      </geometry>
    </collision>
  </link>
  <joint name="fix_2" type="fixed">
    <parent link="u1"/>
    <child link="u2"/>
    <origin xyz="0 0 0.017"/>
    <axis xyz="0 0 1"/>
  </joint>
  <link name="u2">
    <visual>
      <origin rpy="0 0 0" xyz="0 0 0.0015"/>
      <geometry>
        <box size="0.02 0.055 0.003"/>
      </geometry>
      <material name="black"/>
    </visual>
    <inertial>
      <origin rpy="0 0 0" xyz="0 0 0.0015"/>
      <mass value="0.00561"/>
      <inertia ixx="1.418395e-06" ixy="0.0" ixz="0.0" iyy="1.912075e-07" iyz="0.0" izz="1.6011875e-06"/>
    </inertial>
    <collision>
      <origin rpy="0 0 0" xyz="0 0 0.0015"/>
      <geometry>
        <box size="0.02 0.055 0.003"/>
      </geometry>
    </collision>
  </link>
  <joint name="fix_3" type="fixed">
    <parent link="u2"/>
    <child link="u3"/>
    <origin xyz="0 0 0.003"/>
    <axis xyz="0 0 1"/>
  </joint>
  <link name="u3">
    <visual>
      <origin rpy="0 0 0" xyz="0 0 0.005"/>
      <geometry>
        <box size="0.02 0.04 0.01"/>
      </geometry>
      <material name="black"/>
    </visual>
    <inertial>
      <origin rpy="0 0 0" xyz="0 0 0.005"/>
      <mass value="0.0136"/>
      <inertia ixx="1.92666666667e-06" ixy="0.0" ixz="0.0" iyy="5.66666666667e-07" iyz="0.0" izz="2.26666666667e-06"/>
    </inertial>
    <collision>
      <origin rpy="0 0 0" xyz="0 0 0.005"/>
      <geometry>
        <box size="0.02 0.04 0.01"/>
      </geometry>
    </collision>
  </link>
  <joint name="joint1" type="revolute">
    <parent link="u3"/>
    <child link="h0"/>
    <origin xyz="0 0.01 0.01"/>
    <axis xyz="0 0 1"/>
    <dynamics damping="0.03" friction="0.015"/>
    <limit effort="2.0" lower="-1.57079632679" upper="1.57079632679" velocity="3.0"/>
  </joint>
  <!--
  <transmission name="joint1_tran">
    <type>transmission_interface/SimpleTransmission</type>
    <joint name="joint1">
      <hardwareInterface>hardware_interface/EffortJointInterface</hardwareInterface>
    </joint>
    <actuator name="joint1_motor">
      <hardwareInterface>hardware_interface/EffortJointInterface</hardwareInterface>
      <mechanicalReduction>1</mechanicalReduction>
    </actuator>
  </transmission>
  -->
  <link name="h0">
    <visual>
      <origin rpy="0 0 0" xyz="0 0.009 0.0025"/>
      <geometry>
        <box size="0.012 0.03 0.005"/>
      </geometry>
      <material name="grey"/>
    </visual>
    <inertial>
      <origin rpy="0 0 0" xyz="0 0.009 0.0025"/>
      <mass value="0.00306"/>
      <inertia ixx="2.35875e-07" ixy="0.0" ixz="0.0" iyy="4.3095e-08" iyz="0.0" izz="2.6622e-07"/>
    </inertial>
    <collision>
      <origin rpy="0 0 0" xyz="0 0.009 0.0025"/>
      <geometry>
        <box size="0.012 0.03 0.005"/>
      </geometry>
    </collision>
  </link>
</robot>

